Workbook
Name NativeTimeline_Order__Date: #N/A
Name OrderID: Valid_Data!$B$6:$J$6
Name Slicer_City: #N/A
Name Slicer_Product: #N/A
Name Slicer_Region: #N/A

Sheet Messy_Sales_Data
D2: Raw Source Data
C5: OrderID | D5: Order Date | E5: City | F5: Product | G5: Sales | H5: Quantity | I5: Customer Name | J5: Region
C6: 1001 | D6: 01-01-25 | E6: Mumbai | F6: Tablet | G6: 21000 | H6: 3 | I6: Neha | J6: WEST
C7: 1002 | D7: 02/01/2025 | E7: Mumbai | F7: LAPTOP | H7: 2 | I7: Amit | J7: north
C8: 1003 | D8: 03-01-25 | E8: Chennai | F8: Laptop | H8: 1 | I8: Arjun | J8: West
C9: 1004 | D9: 04-01-25 | E9: Bangalore | F9: Tablet | G9: 20000 | I9: Pooja | J9: WEST
C10: 1005 | D10: 05/01/2025 | E10: Delhi | F10: Mobile | G10: 53000 | H10: 3 | I10: Rahul | J10: East
C11: 1006 | D11: 06-01-2025 | E11: Delhi | F11: Mobile | H11: 1 | I11: Pooja | J11: South
C12: 1007 | D12: 07-01-2025 | E12: Delhi | F12: LAPTOP | G12: 15000 | H12: 2 | I12: Ravi | J12: West
C13: 1008 | D13: 08/01/2025 | E13: Chennai | F13: mobile | H13: 2 | I13: Arjun | J13: WEST
C14: 1009 | D14: 09-01-2025 | E14: Bangalore | F14: Laptop | G14: 53000 | H14: 1 | I14: Anita | J14: WEST
C15: 1010 | D15: 10-01-2025 | E15: Mumbai | F15: Tablet | G15: 52000 | H15: 2 | I15: Rahul | J15: north
C16: 1011 | D16: 11/01/2025 | E16: Delhi | F16: Tablet | G16: 52000 | I16: Arjun | J16: West
C17: 1012 | D17: 12/01/2025 | E17: Bangalore | F17: Mobile | G17: 21000 | H17: 2 | I17: Amit | J17: WEST
C18: 1013 | D18: 13-01-25 | E18: Chennai | F18: Tablet | G18: 21000 | H18: 1 | I18: Amit | J18: East
C19: 1014 | D19: 14-01-25 | E19: Mumbai | F19: Laptop | G19: 53000 | H19: 1 | I19: Neha | J19: WEST
C20: 1015 | D20: 15/01/2025 | E20: Kolkata | F20: Mobile | G20: 48000 | H20: 3 | I20: Karan | J20: West
C21: 1016 | D21: 16-01-25 | E21: Mumbai | F21: Mobile | G21: 15000 | H21: 3 | I21: Karan | J21: East
C22: 1017 | D22: 17-01-25 | E22: Bangalore | F22: Mobile | G22: 48000 | H22: 2 | I22: Neha | J22: WEST
C23: 1018 | D23: 18-01-2025 | E23: Bangalore | F23: LAPTOP | G23: 48000 | H23: 1 | I23: Ravi | J23: West
C24: 1019 | D24: 19-01-2025 | E24: Delhi | F24: Laptop | G24: 20000 | H24: 2 | I24: Rahul | J24: north
C25: 1020 | D25: 20-01-25 | E25: Delhi | F25: Mobile | G25: 53000 | I25: Neha | J25: North
C26: 1021 | D26: 21-01-25 | E26: Kolkata | F26: Laptop | G26: 53000 | H26: 1 | I26: Ravi | J26: South
C27: 1022 | D27: 22-01-2025 | E27: Mumbai | F27: LAPTOP | G27: 21000 | I27: Anita | J27: WEST
C28: 1023 | D28: 23-01-25 | E28: Bangalore | F28: Laptop | G28: 55000 | H28: 2 | I28: Amit | J28: West
C29: 1024 | D29: 24-01-2025 | E29: Bangalore | F29: Mobile | G29: 15000 | H29: 3 | I29: Rahul | J29: WEST
C30: 1025 | D30: 25-01-2025 | E30: Kolkata | F30: Mobile | G30: 52000 | H30: 2 | I30: Rahul | J30: WEST
C31: 1026 | D31: 26-01-25 | E31: Delhi | F31: Tablet | G31: 15000 | H31: 1 | I31: Pooja | J31: north
C32: 1027 | D32: 27-01-2025 | E32: Kolkata | F32: Mobile | G32: 15000 | I32: Neha | J32: East
C33: 1028 | D33: 28-01-2025 | E33: Bangalore | F33: Laptop | G33: 52000 | H33: 3 | I33: Neha | J33: north
C34: 1029 | D34: 29-01-2025 | E34: Bangalore | F34: Mobile | G34: 52000 | H34: 2 | I34: Karan | J34: WEST
C35: 1030 | D35: 30/01/2025 | E35: Kolkata | F35: Mobile | G35: 48000 | H35: 1 | I35: Ravi | J35: WEST
C36: 1031 | D36: 31/01/2025 | E36: Chennai | F36: Mobile | G36: 15000 | H36: 1 | I36: Ravi | J36: north
C37: 1032 | D37: 01-02-25 | E37: Bangalore | F37: Laptop | G37: 52000 | I37: Pooja | J37: East
C38: 1033 | D38: 02/02/2025 | E38: Chennai | F38: Mobile | G38: 20000 | H38: 3 | I38: Arjun | J38: WEST
C39: 1034 | D39: 03-02-25 | E39: Chennai | F39: mobile | G39: 20000 | H39: 3 | I39: Rahul | J39: North
C40: 1035 | D40: 04-02-2025 | E40: Kolkata | F40: Mobile | H40: 1 | I40: Anita | J40: West
C41: 1036 | D41: 05-02-2025 | E41: Mumbai | F41: LAPTOP | G41: 15000 | H41: 3 | I41: Karan | J41: South
C42: 1037 | D42: 06-02-25 | E42: Mumbai | F42: LAPTOP | G42: 55000 | H42: 1 | I42: Karan | J42: north
C43: 1038 | D43: 07/02/2025 | E43: Bangalore | F43: mobile | G43: 20000 | H43: 2 | I43: Pooja | J43: East
...

Sheet Refined_Data
D2: Cleaned Data with Missing Values
B5: OrderID | C5: Order Date | D5: City | E5: Product | F5: Sales | G5: Quantity | H5: Customer Name | I5: Region | J5: Status Check
B6: 1001 | C6: 45658 | D6: Mumbai | E6: Tablet | F6: 21000 | G6: 3 | H6: Neha | I6: West | J6: =IFERROR(IF(AND(Table1[[#This Row],[Sales]]=0,Table1[[#This Row],[Quantity]]<>0),"Sales Missing",IF(AND(Table1[[#This Row],[Sales]]<>0,Table1[[#This Row],[Quantity]]=0),"Quantity Missing",IF(AND(Table1[[#This Row],[Sales]]=0,Table1[[#This Row],[Quantity]]=0),"Both Missing","Valid Response"))),"No Data") -> Valid Response
B7: 1002 | C7: 45659 | D7: Mumbai | E7: Laptop | F7: 0 | G7: 2 | H7: Amit | I7: North | J7: =IFERROR(IF(AND(Table1[[#This Row],[Sales]]=0,Table1[[#This Row],[Quantity]]<>0),"Sales Missing",IF(AND(Table1[[#This Row],[Sales]]<>0,Table1[[#This Row],[Quantity]]=0),"Quantity Missing",IF(AND(Table1[[#This Row],[Sales]]=0,Table1[[#This Row],[Quantity]]=0),"Both Missing","Valid Response"))),"No Data") -> Sales Missing
B8: 1003 | C8: 45660 | D8: Chennai | E8: Laptop | F8: 0 | G8: 1 | H8: Arjun | I8: West | J8: =IFERROR(IF(AND(Table1[[#This Row],[Sales]]=0,Table1[[#This Row],[Quantity]]<>0),"Sales Missing",IF(AND(Table1[[#This Row],[Sales]]<>0,Table1[[#This Row],[Quantity]]=0),"Quantity Missing",IF(AND(Table1[[#This Row],[Sales]]=0,Table1[[#This Row],[Quantity]]=0),"Both Missing","Valid Response"))),"No Data") -> Sales Missing
B9: 1004 | C9: 45661 | D9: Bangalore | E9: Tablet | F9: 20000 | G9: 0 | H9: Pooja | I9: West | J9: =IFERROR(IF(AND(Table1[[#This Row],[Sales]]=0,Table1[[#This Row],[Quantity]]<>0),"Sales Missing",IF(AND(Table1[[#This Row],[Sales]]<>0,Table1[[#This Row],[Quantity]]=0),"Quantity Missing",IF(AND(Table1[[#This Row],[Sales]]=0,Table1[[#This Row],[Quantity]]=0),"Both Missing","Valid Response"))),"No Data") -> Quantity Missing
B10: 1005 | C10: 45662 | D10: Delhi | E10: Mobile | F10: 53000 | G10: 3 | H10: Rahul | I10: East | J10: =IFERROR(IF(AND(Table1[[#This Row],[Sales]]=0,Table1[[#This Row],[Quantity]]<>0),"Sales Missing",IF(AND(Table1[[#This Row],[Sales]]<>0,Table1[[#This Row],[Quantity]]=0),"Quantity Missing",IF(AND(Table1[[#This Row],[Sales]]=0,Table1[[#This Row],[Quantity]]=0),"Both Missing","Valid Response"))),"No Data") -> Valid Response
B11: 1006 | C11: 45663 | D11: Delhi | E11: Mobile | F11: 0 | G11: 1 | H11: Pooja | I11: South | J11: =IFERROR(IF(AND(Table1[[#This Row],[Sales]]=0,Table1[[#This Row],[Quantity]]<>0),"Sales Missing",IF(AND(Table1[[#This Row],[Sales]]<>0,Table1[[#This Row],[Quantity]]=0),"Quantity Missing",IF(AND(Table1[[#This Row],[Sales]]=0,Table1[[#This Row],[Quantity]]=0),"Both Missing","Valid Response"))),"No Data") -> Sales Missing
B12: 1007 | C12: 45664 | D12: Delhi | E12: Laptop | F12: 15000 | G12: 2 | H12: Ravi | I12: West | J12: =IFERROR(IF(AND(Table1[[#This Row],[Sales]]=0,Table1[[#This Row],[Quantity]]<>0),"Sales Missing",IF(AND(Table1[[#This Row],[Sales]]<>0,Table1[[#This Row],[Quantity]]=0),"Quantity Missing",IF(AND(Table1[[#This Row],[Sales]]=0,Table1[[#This Row],[Quantity]]=0),"Both Missing","Valid Response"))),"No Data") -> Valid Response
B13: 1008 | C13: 45665 | D13: Chennai | E13: Mobile | F13: 0 | G13: 2 | H13: Arjun | I13: West | J13: =IFERROR(IF(AND(Table1[[#This Row],[Sales]]=0,Table1[[#This Row],[Quantity]]<>0),"Sales Missing",IF(AND(Table1[[#This Row],[Sales]]<>0,Table1[[#This Row],[Quantity]]=0),"Quantity Missing",IF(AND(Table1[[#This Row],[Sales]]=0,Table1[[#This Row],[Quantity]]=0),"Both Missing","Valid Response"))),"No Data") -> Sales Missing
B14: 1009 | C14: 45666 | D14: Bangalore | E14: Laptop | F14: 53000 | G14: 1 | H14: Anita | I14: West | J14: =IFERROR(IF(AND(Table1[[#This Row],[Sales]]=0,Table1[[#This Row],[Quantity]]<>0),"Sales Missing",IF(AND(Table1[[#This Row],[Sales]]<>0,Table1[[#This Row],[Quantity]]=0),"Quantity Missing",IF(AND(Table1[[#This Row],[Sales]]=0,Table1[[#This Row],[Quantity]]=0),"Both Missing","Valid Response"))),"No Data") -> Valid Response
B15: 1010 | C15: 45667 | D15: Mumbai | E15: Tablet | F15: 52000 | G15: 2 | H15: Rahul | I15: North | J15: =IFERROR(IF(AND(Table1[[#This Row],[Sales]]=0,Table1[[#This Row],[Quantity]]<>0),"Sales Missing",IF(AND(Table1[[#This Row],[Sales]]<>0,Table1[[#This Row],[Quantity]]=0),"Quantity Missing",IF(AND(Table1[[#This Row],[Sales]]=0,Table1[[#This Row],[Quantity]]=0),"Both Missing","Valid Response"))),"No Data") -> Valid Response
B16: 1011 | C16: 45668 | D16: Delhi | E16: Tablet | F16: 52000 | G16: 0 | H16: Arjun | I16: West | J16: =IFERROR(IF(AND(Table1[[#This Row],[Sales]]=0,Table1[[#This Row],[Quantity]]<>0),"Sales Missing",IF(AND(Table1[[#This Row],[Sales]]<>0,Table1[[#This Row],[Quantity]]=0),"Quantity Missing",IF(AND(Table1[[#This Row],[Sales]]=0,Table1[[#This Row],[Quantity]]=0),"Both Missing","Valid Response"))),"No Data") -> Quantity Missing
B17: 1012 | C17: 45669 | D17: Bangalore | E17: Mobile | F17: 21000 | G17: 2 | H17: Amit | I17: West | J17: =IFERROR(IF(AND(Table1[[#This Row],[Sales]]=0,Table1[[#This Row],[Quantity]]<>0),"Sales Missing",IF(AND(Table1[[#This Row],[Sales]]<>0,Table1[[#This Row],[Quantity]]=0),"Quantity Missing",IF(AND(Table1[[#This Row],[Sales]]=0,Table1[[#This Row],[Quantity]]=0),"Both Missing","Valid Response"))),"No Data") -> Valid Response
... B505: 1500 | C505: 45677 | D505: Delhi | E505: Laptop | F505: 0 | G505: 1 | H505: Neha | I505: East | J505: =IFERROR(IF(AND(Table1[[#This Row],[Sales]]=0,Table1[[#This Row],[Quantity]]<>0),"Sales Missing",IF(AND(Table1[[#This Row],[Sales]]<>0,Table1[[#This Row],[Quantity]]=0),"Quantity Missing",IF(AND(Table1[[#This Row],[Sales]]=0,Table1[[#This Row],[Quantity]]=0),"Both Missing","Valid Response"))),"No Data") -> Sales Missing
F506: =SUBTOTAL(109,Table1[Sales]) -> 16084000 | G506: =SUBTOTAL(109,Table1[Quantity]) -> 748
F507: =COUNT(Table1[Sales]) -> 500 | G507: =COUNT(Table1[Quantity]) -> 500

Sheet Valid_Data
D2: Analysis Ready Data Table
B6: OrderID | C6: Order Date | D6: City | E6: Product | F6: Sales | G6: Quantity | H6: Customer Name | I6: Region | J6: Status Check
B7: 1001 | C7: 45658 | D7: Mumbai | E7: Tablet | F7: 21000 | G7: 3 | H7: Neha | I7: West | J7: Valid Response
B8: 1005 | C8: 45662 | D8: Delhi | E8: Mobile | F8: 53000 | G8: 3 | H8: Rahul | I8: East | J8: Valid Response
B9: 1007 | C9: 45664 | D9: Delhi | E9: Laptop | F9: 15000 | G9: 2 | H9: Ravi | I9: West | J9: Valid Response
B10: 1009 | C10: 45666 | D10: Bangalore | E10: Laptop | F10: 53000 | G10: 1 | H10: Anita | I10: West | J10: Valid Response
B11: 1010 | C11: 45667 | D11: Mumbai | E11: Tablet | F11: 52000 | G11: 2 | H11: Rahul | I11: North | J11: Valid Response
B12: 1012 | C12: 45669 | D12: Bangalore | E12: Mobile | F12: 21000 | G12: 2 | H12: Amit | I12: West | J12: Valid Response
B13: 1013 | C13: 45670 | D13: Chennai | E13: Tablet | F13: 21000 | G13: 1 | H13: Amit | I13: East | J13: Valid Response
B14: 1014 | C14: 45671 | D14: Mumbai | E14: Laptop | F14: 53000 | G14: 1 | H14: Neha | I14: West | J14: Valid Response
B15: 1015 | C15: 45672 | D15: Kolkata | E15: Mobile | F15: 48000 | G15: 3 | H15: Karan | I15: West | J15: Valid Response
B16: 1016 | C16: 45673 | D16: Mumbai | E16: Mobile | F16: 15000 | G16: 3 | H16: Karan | I16: East | J16: Valid Response
B17: 1017 | C17: 45674 | D17: Bangalore | E17: Mobile | F17: 48000 | G17: 2 | H17: Neha | I17: West | J17: Valid Response
B18: 1018 | C18: 45675 | D18: Bangalore | E18: Laptop | F18: 48000 | G18: 1 | H18: Ravi | I18: West | J18: Valid Response
... B348: 1498 | C348: 45675 | D348: Delhi | E348: Laptop | F348: 21000 | G348: 3 | H348: Pooja | I348: West | J348: Valid Response
F349: =SUBTOTAL(109,Table2[Sales]) -> 12177000 | G349: =SUBTOTAL(109,Table2[Quantity]) -> 682

Sheet Pivot_Table_Analysis
E2: Pivot_Table_Analysis
G5: Quantity | H5: (All)
B7: Product | C7: Sum of Sales | G7: Region | H7: Sum of Quantity | I7: Sum of Sales | J7: Count of OrderID
B8: Laptop | C8: 5511000 | G8: West | H8: 220 | I8: 4013000 | J8: 114
B9: Mobile | C9: 4641000 | G9: East | H9: 133 | I9: 2365000 | J9: 65
B10: Tablet | C10: 2025000 | G10: South | H10: 105 | I10: 1977000 | J10: 55
B11: Grand Total | C11: 12177000 | G11: North | H11: 224 | I11: 3822000 | J11: 108
G12: Grand Total | H12: 682 | I12: 12177000 | J12: 342
B15: City | C15: Sum of Quantity | D15: Sum of Sales | G15: Sum of Sales | H15: Column Labels
B16: Bangalore | C16: 208 | D16: 3643000 | G16: Months | H16: Laptop | I16: Mobile | J16: Tablet | K16: Grand Total
B17: Chennai | C17: 96 | D17: 1742000 | G17: Jan | H17: 1712000 | I17: 1487000 | J17: 599000 | K17: 3798000
B18: Delhi | C18: 178 | D18: 3103000 | G18: Feb | H18: 1261000 | I18: 977000 | J18: 458000 | K18: 2696000
B19: Kolkata | C19: 102 | D19: 1826000 | G19: Mar | H19: 1104000 | I19: 1132000 | J19: 485000 | K19: 2721000
B20: Mumbai | C20: 98 | D20: 1863000 | G20: Apr | H20: 1434000 | I20: 1045000 | J20: 483000 | K20: 2962000
B21: Grand Total | C21: 682 | D21: 12177000 | G21: Grand Total | H21: 5511000 | I21: 4641000 | J21: 2025000 | K21: 12177000

Sheet Dynamic_Sales_Dashboard
F2: Dynamic MIS Sales Dashboard
B5: Total Revenue | D5: Total Quantity | F5: Average Order Value | H5: Total orders | J5: Top Product | L5: Top Region | N5: Top City
B6: =GETPIVOTDATA("Sales",Pivot_Table_Analysis!$B$7) -> 12177000 | D6: =GETPIVOTDATA("Sum of Quantity",Pivot_Table_Analysis!$G$7) -> 682 | F6: =$B$6/$H$6 -> 35605.263 | H6: =GETPIVOTDATA("Count of OrderID",Pivot_Table_Analysis!$G$7) -> 342 | J6: =IFERROR(INDEX(Pivot_Table_Analysis!B8:B10,MATCH(MAX(Pivot_Table_Analysis!C8:C10),Pivot_Table_Analysis!C8:C10,0)),"No Data") -> Laptop | L6: =IFERROR(INDEX(Pivot_Table_Analysis!G8:G11,MATCH(MAX(Pivot_Table_Analysis!I8:I11),Pivot_Table_Analysis!I8:I11,0)),"No Data") -> West | N6: =IFERROR(INDEX(Pivot_Table_Analysis!B16:B20,MATCH(MAX(Pivot_Table_Analysis!D16:D20),Pivot_Table_Analysis!D16:D20,0)),"No data") -> Bangalore
Q8: S. No. | R8: Key Insights :
Q11: 1 | R11: Laptop spearheaded sales at ₹5.51M.
Q12: 2 | R12: West outperformed regions with ₹4.01M revenue.
Q13: 3 | R13: Bangalore topped cities at ₹3.64M sales.
Q14: 4 | R14: Tablet trailed products at ₹2.03M revenue.
Q15: 5 | R15: 342 orders yielded ₹12.18M, averaging ₹35.6K (AOV) each.
